[2025-08-05 08:32:51,802] [log.py:228] [log:log_response] [ERROR]- Internal Server Error: /CabinetManage/CabinetManage_edit/
Traceback (most recent call last):
  File "C:\Python3129\mecheck\lib\site-packages\django\core\handlers\exception.py", line 34, in inner
    response = get_response(request)
  File "C:\Python3129\mecheck\lib\site-packages\django\core\handlers\base.py", line 126, in _get_response
    response = self.process_exception_by_middleware(e, request)
  File "C:\Python3129\mecheck\lib\site-packages\django\core\handlers\base.py", line 124, in _get_response
    response = wrapped_callback(request, *callback_args, **callback_kwargs)
  File "C:\Python3129\mecheck\lib\site-packages\django\views\decorators\csrf.py", line 54, in wrapped_view
    return view_func(*args, **kwargs)
  File "C:\djangoproject\DMS\CabinetManage\views.py", line 296, in CabinetManage_edit
    return HttpResponse(json.dumps(data), content_type="application/json")
  File "C:\Python372\lib\json\__init__.py", line 231, in dumps
    return _default_encoder.encode(obj)
  File "C:\Python372\lib\json\encoder.py", line 199, in encode
    chunks = self.iterencode(o, _one_shot=True)
  File "C:\Python372\lib\json\encoder.py", line 257, in iterencode
    return _iterencode(o, 0)
  File "C:\Python372\lib\json\encoder.py", line 179, in default
    raise TypeError(f'Object of type {o.__class__.__name__} '
TypeError: Object of type datetime is not JSON serializable
[2025-08-05 08:32:51,814] [UserIP.py:90] [UserIP:process_response] [CRITICAL]- 系统错误Expecting value: line 1 column 1 (char 0)
[2025-08-05 08:32:51,835] [basehttp.py:154] [basehttp:log_message] [ERROR]- "POST /CabinetManage/CabinetManage_edit/ HTTP/1.1" 500 151430
[2025-08-05 08:48:01,463] [UserIP.py:90] [UserIP:process_response] [CRITICAL]- 系统错误Expecting value: line 1 column 1 (char 0)
[2025-08-05 12:50:52,831] [UserIP.py:90] [UserIP:process_response] [CRITICAL]- 系统错误Expecting value: line 1 column 1 (char 0)
[2025-08-05 13:13:47,105] [UserIP.py:90] [UserIP:process_response] [CRITICAL]- 系统错误Expecting value: line 1 column 1 (char 0)
[2025-08-05 15:26:11,723] [log.py:228] [log:log_response] [ERROR]- Internal Server Error: /CabinetManage/CabinetManage_edit/
Traceback (most recent call last):
  File "C:\Python3129\mecheck\lib\site-packages\django\core\handlers\exception.py", line 34, in inner
    response = get_response(request)
  File "C:\Python3129\mecheck\lib\site-packages\django\core\handlers\base.py", line 126, in _get_response
    response = self.process_exception_by_middleware(e, request)
  File "C:\Python3129\mecheck\lib\site-packages\django\core\handlers\base.py", line 124, in _get_response
    response = wrapped_callback(request, *callback_args, **callback_kwargs)
  File "C:\Python3129\mecheck\lib\site-packages\django\views\decorators\csrf.py", line 54, in wrapped_view
    return view_func(*args, **kwargs)
  File "C:\djangoproject\DMS\CabinetManage\views.py", line 686, in CabinetManage_edit
    print(data['"cabinets"'])
KeyError: '"cabinets"'
[2025-08-05 15:26:11,725] [UserIP.py:90] [UserIP:process_response] [CRITICAL]- 系统错误Expecting value: line 1 column 1 (char 0)
[2025-08-05 15:26:11,725] [basehttp.py:154] [basehttp:log_message] [ERROR]- "POST /CabinetManage/CabinetManage_edit/ HTTP/1.1" 500 112715
[2025-08-05 16:10:59,483] [log.py:228] [log:log_response] [ERROR]- Internal Server Error: /DeviceLNV/M_edit/
Traceback (most recent call last):
  File "C:\Python3129\mecheck\lib\site-packages\django\core\handlers\exception.py", line 34, in inner
    response = get_response(request)
  File "C:\Python3129\mecheck\lib\site-packages\django\core\handlers\base.py", line 126, in _get_response
    response = self.process_exception_by_middleware(e, request)
  File "C:\Python3129\mecheck\lib\site-packages\django\core\handlers\base.py", line 124, in _get_response
    response = wrapped_callback(request, *callback_args, **callback_kwargs)
  File "C:\Python3129\mecheck\lib\site-packages\django\views\decorators\csrf.py", line 54, in wrapped_view
    return view_func(*args, **kwargs)
  File "C:\djangoproject\DMS\DeviceLNV\views.py", line 5822, in M_edit
    Pers_list = ImportPersonalInfo()
  File "C:\djangoproject\DMS\DeviceLNV\views.py", line 7367, in ImportPersonalInfo
    if json.loads(r.text)["token"]:
  File "C:\Python372\lib\json\__init__.py", line 348, in loads
    return _default_decoder.decode(s)
  File "C:\Python372\lib\json\decoder.py", line 337, in decode
    obj, end = self.raw_decode(s, idx=_w(s, 0).end())
  File "C:\Python372\lib\json\decoder.py", line 355, in raw_decode
    raise JSONDecodeError("Expecting value", s, err.value) from None
json.decoder.JSONDecodeError: Expecting value: line 1 column 1 (char 0)
[2025-08-05 16:10:59,488] [basehttp.py:154] [basehttp:log_message] [ERROR]- "GET /DeviceLNV/M_edit/ HTTP/1.1" 500 141657
[2025-08-05 16:12:54,590] [log.py:228] [log:log_response] [ERROR]- Internal Server Error: /DeviceLNV/M_edit/
Traceback (most recent call last):
  File "C:\Python3129\mecheck\lib\site-packages\django\core\handlers\exception.py", line 34, in inner
    response = get_response(request)
  File "C:\Python3129\mecheck\lib\site-packages\django\core\handlers\base.py", line 126, in _get_response
    response = self.process_exception_by_middleware(e, request)
  File "C:\Python3129\mecheck\lib\site-packages\django\core\handlers\base.py", line 124, in _get_response
    response = wrapped_callback(request, *callback_args, **callback_kwargs)
  File "C:\Python3129\mecheck\lib\site-packages\django\views\decorators\csrf.py", line 54, in wrapped_view
    return view_func(*args, **kwargs)
  File "C:\djangoproject\DMS\DeviceLNV\views.py", line 5876, in M_edit
    Pers_list = ImportPersonalInfo()
  File "C:\djangoproject\DMS\DeviceLNV\views.py", line 69, in ImportPersonalInfo
    if json.loads(r.text)["token"]:
  File "C:\Python372\lib\json\__init__.py", line 348, in loads
    return _default_decoder.decode(s)
  File "C:\Python372\lib\json\decoder.py", line 337, in decode
    obj, end = self.raw_decode(s, idx=_w(s, 0).end())
  File "C:\Python372\lib\json\decoder.py", line 355, in raw_decode
    raise JSONDecodeError("Expecting value", s, err.value) from None
json.decoder.JSONDecodeError: Expecting value: line 1 column 1 (char 0)
[2025-08-05 16:12:54,603] [basehttp.py:154] [basehttp:log_message] [ERROR]- "GET /DeviceLNV/M_edit/ HTTP/1.1" 500 141649
[2025-08-05 16:12:56,321] [log.py:228] [log:log_response] [ERROR]- Internal Server Error: /DeviceLNV/M_edit/
Traceback (most recent call last):
  File "C:\Python3129\mecheck\lib\site-packages\django\core\handlers\exception.py", line 34, in inner
    response = get_response(request)
  File "C:\Python3129\mecheck\lib\site-packages\django\core\handlers\base.py", line 126, in _get_response
    response = self.process_exception_by_middleware(e, request)
  File "C:\Python3129\mecheck\lib\site-packages\django\core\handlers\base.py", line 124, in _get_response
    response = wrapped_callback(request, *callback_args, **callback_kwargs)
  File "C:\Python3129\mecheck\lib\site-packages\django\views\decorators\csrf.py", line 54, in wrapped_view
    return view_func(*args, **kwargs)
  File "C:\djangoproject\DMS\DeviceLNV\views.py", line 5876, in M_edit
    Pers_list = ImportPersonalInfo()
  File "C:\djangoproject\DMS\DeviceLNV\views.py", line 69, in ImportPersonalInfo
    if json.loads(r.text)["token"]:
  File "C:\Python372\lib\json\__init__.py", line 348, in loads
    return _default_decoder.decode(s)
  File "C:\Python372\lib\json\decoder.py", line 337, in decode
    obj, end = self.raw_decode(s, idx=_w(s, 0).end())
  File "C:\Python372\lib\json\decoder.py", line 355, in raw_decode
    raise JSONDecodeError("Expecting value", s, err.value) from None
json.decoder.JSONDecodeError: Expecting value: line 1 column 1 (char 0)
[2025-08-05 16:12:56,323] [basehttp.py:154] [basehttp:log_message] [ERROR]- "GET /DeviceLNV/M_edit/ HTTP/1.1" 500 141649
[2025-08-05 16:13:26,920] [log.py:228] [log:log_response] [ERROR]- Internal Server Error: /DeviceLNV/M_edit/
Traceback (most recent call last):
  File "C:\Python3129\mecheck\lib\site-packages\django\core\handlers\exception.py", line 34, in inner
    response = get_response(request)
  File "C:\Python3129\mecheck\lib\site-packages\django\core\handlers\base.py", line 126, in _get_response
    response = self.process_exception_by_middleware(e, request)
  File "C:\Python3129\mecheck\lib\site-packages\django\core\handlers\base.py", line 124, in _get_response
    response = wrapped_callback(request, *callback_args, **callback_kwargs)
  File "C:\Python3129\mecheck\lib\site-packages\django\views\decorators\csrf.py", line 54, in wrapped_view
    return view_func(*args, **kwargs)
  File "C:\djangoproject\DMS\DeviceLNV\views.py", line 5876, in M_edit
    Pers_list = ImportPersonalInfo()
  File "C:\djangoproject\DMS\DeviceLNV\views.py", line 69, in ImportPersonalInfo
    if json.loads(r.text)["token"]:
  File "C:\Python372\lib\json\__init__.py", line 348, in loads
    return _default_decoder.decode(s)
  File "C:\Python372\lib\json\decoder.py", line 337, in decode
    obj, end = self.raw_decode(s, idx=_w(s, 0).end())
  File "C:\Python372\lib\json\decoder.py", line 355, in raw_decode
    raise JSONDecodeError("Expecting value", s, err.value) from None
json.decoder.JSONDecodeError: Expecting value: line 1 column 1 (char 0)
[2025-08-05 16:13:26,926] [basehttp.py:154] [basehttp:log_message] [ERROR]- "GET /DeviceLNV/M_edit/ HTTP/1.1" 500 141649
[2025-08-05 16:13:41,810] [log.py:228] [log:log_response] [ERROR]- Internal Server Error: /SysAdmin/UserInfo-edit/
Traceback (most recent call last):
  File "C:\Python3129\mecheck\lib\site-packages\django\core\handlers\exception.py", line 34, in inner
    response = get_response(request)
  File "C:\Python3129\mecheck\lib\site-packages\django\core\handlers\base.py", line 126, in _get_response
    response = self.process_exception_by_middleware(e, request)
  File "C:\Python3129\mecheck\lib\site-packages\django\core\handlers\base.py", line 124, in _get_response
    response = wrapped_callback(request, *callback_args, **callback_kwargs)
  File "C:\Python3129\mecheck\lib\site-packages\django\views\decorators\csrf.py", line 54, in wrapped_view
    return view_func(*args, **kwargs)
  File "C:\djangoproject\DMS\app01\views.py", line 868, in UserInfoedit
    Pers_list = ImportPersonalInfo()
  File "C:\djangoproject\DMS\app01\views.py", line 62, in ImportPersonalInfo
    if json.loads(r.text)["token"]:
  File "C:\Python372\lib\json\__init__.py", line 348, in loads
    return _default_decoder.decode(s)
  File "C:\Python372\lib\json\decoder.py", line 337, in decode
    obj, end = self.raw_decode(s, idx=_w(s, 0).end())
  File "C:\Python372\lib\json\decoder.py", line 355, in raw_decode
    raise JSONDecodeError("Expecting value", s, err.value) from None
json.decoder.JSONDecodeError: Expecting value: line 1 column 1 (char 0)
[2025-08-05 16:13:41,836] [UserIP.py:90] [UserIP:process_response] [CRITICAL]- 系统错误Expecting value: line 1 column 1 (char 0)
[2025-08-05 16:13:41,844] [basehttp.py:154] [basehttp:log_message] [ERROR]- "POST /SysAdmin/UserInfo-edit/ HTTP/1.1" 500 151179
[2025-08-05 16:14:36,145] [UserIP.py:90] [UserIP:process_response] [CRITICAL]- 系统错误Expecting value: line 1 column 1 (char 0)
[2025-08-05 16:14:36,777] [log.py:228] [log:log_response] [ERROR]- Internal Server Error: /SysAdmin/UserInfo-edit/
Traceback (most recent call last):
  File "C:\Python3129\mecheck\lib\site-packages\django\core\handlers\exception.py", line 34, in inner
    response = get_response(request)
  File "C:\Python3129\mecheck\lib\site-packages\django\core\handlers\base.py", line 126, in _get_response
    response = self.process_exception_by_middleware(e, request)
  File "C:\Python3129\mecheck\lib\site-packages\django\core\handlers\base.py", line 124, in _get_response
    response = wrapped_callback(request, *callback_args, **callback_kwargs)
  File "C:\Python3129\mecheck\lib\site-packages\django\views\decorators\csrf.py", line 54, in wrapped_view
    return view_func(*args, **kwargs)
  File "C:\djangoproject\DMS\app01\views.py", line 868, in UserInfoedit
    Pers_list = ImportPersonalInfo()
  File "C:\djangoproject\DMS\app01\views.py", line 62, in ImportPersonalInfo
    if json.loads(r.text)["token"]:
  File "C:\Python372\lib\json\__init__.py", line 348, in loads
    return _default_decoder.decode(s)
  File "C:\Python372\lib\json\decoder.py", line 337, in decode
    obj, end = self.raw_decode(s, idx=_w(s, 0).end())
  File "C:\Python372\lib\json\decoder.py", line 355, in raw_decode
    raise JSONDecodeError("Expecting value", s, err.value) from None
json.decoder.JSONDecodeError: Expecting value: line 1 column 1 (char 0)
[2025-08-05 16:14:36,780] [UserIP.py:90] [UserIP:process_response] [CRITICAL]- 系统错误Expecting value: line 1 column 1 (char 0)
[2025-08-05 16:14:36,780] [basehttp.py:154] [basehttp:log_message] [ERROR]- "POST /SysAdmin/UserInfo-edit/ HTTP/1.1" 500 151189
[2025-08-06 08:55:47,753] [UserIP.py:90] [UserIP:process_response] [CRITICAL]- 系统错误Expecting value: line 1 column 1 (char 0)
