[2025-08-04 09:57:36,353] [UserIP.py:90] [UserIP:process_response] [CRITICAL]- 系统错误Expecting value: line 1 column 1 (char 0)
[2025-08-04 13:56:05,547] [log.py:228] [log:log_response] [ERROR]- Internal Server Error: /CabinetManage/CabinetManage_edit/
Traceback (most recent call last):
  File "C:\Python3129\mecheck\lib\site-packages\django\core\handlers\exception.py", line 34, in inner
    response = get_response(request)
  File "C:\Python3129\mecheck\lib\site-packages\django\core\handlers\base.py", line 126, in _get_response
    response = self.process_exception_by_middleware(e, request)
  File "C:\Python3129\mecheck\lib\site-packages\django\core\handlers\base.py", line 124, in _get_response
    response = wrapped_callback(request, *callback_args, **callback_kwargs)
  File "C:\Python3129\mecheck\lib\site-packages\django\views\decorators\csrf.py", line 54, in wrapped_view
    return view_func(*args, **kwargs)
  File "C:\djangoproject\DMS\CabinetManage\views.py", line 207, in CabinetManage_edit
    Cabinet_obj = Cabinet.objects.create(**Cabinet_create_dic)
AttributeError: 'dict' object has no attribute 'objects'
[2025-08-04 13:56:05,552] [UserIP.py:90] [UserIP:process_response] [CRITICAL]- 系统错误Expecting value: line 1 column 1 (char 0)
[2025-08-04 13:56:05,553] [basehttp.py:154] [basehttp:log_message] [ERROR]- "POST /CabinetManage/CabinetManage_edit/ HTTP/1.1" 500 94494
[2025-08-04 14:03:37,888] [log.py:228] [log:log_response] [ERROR]- Internal Server Error: /CabinetManage/CabinetManage_edit/
Traceback (most recent call last):
  File "C:\Python3129\mecheck\lib\site-packages\django\core\handlers\exception.py", line 34, in inner
    response = get_response(request)
  File "C:\Python3129\mecheck\lib\site-packages\django\core\handlers\base.py", line 126, in _get_response
    response = self.process_exception_by_middleware(e, request)
  File "C:\Python3129\mecheck\lib\site-packages\django\core\handlers\base.py", line 124, in _get_response
    response = wrapped_callback(request, *callback_args, **callback_kwargs)
  File "C:\Python3129\mecheck\lib\site-packages\django\views\decorators\csrf.py", line 54, in wrapped_view
    return view_func(*args, **kwargs)
  File "C:\djangoproject\DMS\CabinetManage\views.py", line 209, in CabinetManage_edit
    for row in Cabinet["gridData"]:
TypeError: 'ModelBase' object is not subscriptable
[2025-08-04 14:03:37,894] [UserIP.py:90] [UserIP:process_response] [CRITICAL]- 系统错误Expecting value: line 1 column 1 (char 0)
[2025-08-04 14:03:37,896] [basehttp.py:154] [basehttp:log_message] [ERROR]- "POST /CabinetManage/CabinetManage_edit/ HTTP/1.1" 500 94767
[2025-08-04 14:05:23,808] [UserIP.py:90] [UserIP:process_response] [CRITICAL]- 系统错误Expecting value: line 1 column 1 (char 0)
[2025-08-04 14:05:47,695] [log.py:228] [log:log_response] [ERROR]- Internal Server Error: /CabinetManage/CabinetManage_edit/
Traceback (most recent call last):
  File "C:\Python3129\mecheck\lib\site-packages\django\db\backends\utils.py", line 85, in _execute
    return self.cursor.execute(sql, params)
  File "C:\Python3129\mecheck\lib\site-packages\django\db\backends\mysql\base.py", line 71, in execute
    return self.cursor.execute(query, args)
  File "C:\Python3129\mecheck\lib\site-packages\pymysql\cursors.py", line 170, in execute
    result = self._query(query)
  File "C:\Python3129\mecheck\lib\site-packages\pymysql\cursors.py", line 328, in _query
    conn.query(q)
  File "C:\Python3129\mecheck\lib\site-packages\pymysql\connections.py", line 517, in query
    self._affected_rows = self._read_query_result(unbuffered=unbuffered)
  File "C:\Python3129\mecheck\lib\site-packages\pymysql\connections.py", line 732, in _read_query_result
    result.read()
  File "C:\Python3129\mecheck\lib\site-packages\pymysql\connections.py", line 1075, in read
    first_packet = self.connection._read_packet()
  File "C:\Python3129\mecheck\lib\site-packages\pymysql\connections.py", line 684, in _read_packet
    packet.check_error()
  File "C:\Python3129\mecheck\lib\site-packages\pymysql\protocol.py", line 220, in check_error
    err.raise_mysql_exception(self._data)
  File "C:\Python3129\mecheck\lib\site-packages\pymysql\err.py", line 109, in raise_mysql_exception
    raise errorclass(errno, errval)
pymysql.err.IntegrityError: (1048, "Column 'Brow_at' cannot be null")

The above exception was the direct cause of the following exception:

Traceback (most recent call last):
  File "C:\Python3129\mecheck\lib\site-packages\django\core\handlers\exception.py", line 34, in inner
    response = get_response(request)
  File "C:\Python3129\mecheck\lib\site-packages\django\core\handlers\base.py", line 126, in _get_response
    response = self.process_exception_by_middleware(e, request)
  File "C:\Python3129\mecheck\lib\site-packages\django\core\handlers\base.py", line 124, in _get_response
    response = wrapped_callback(request, *callback_args, **callback_kwargs)
  File "C:\Python3129\mecheck\lib\site-packages\django\views\decorators\csrf.py", line 54, in wrapped_view
    return view_func(*args, **kwargs)
  File "C:\djangoproject\DMS\CabinetManage\views.py", line 233, in CabinetManage_edit
    CabinetGrid.objects.bulk_create(CabinetGrids_list)
  File "C:\Python3129\mecheck\lib\site-packages\django\db\models\manager.py", line 82, in manager_method
    return getattr(self.get_queryset(), name)(*args, **kwargs)
  File "C:\Python3129\mecheck\lib\site-packages\django\db\models\query.py", line 465, in bulk_create
    ids = self._batched_insert(objs_without_pk, fields, batch_size)
  File "C:\Python3129\mecheck\lib\site-packages\django\db\models\query.py", line 1155, in _batched_insert
    self._insert(item, fields=fields, using=self.db)
  File "C:\Python3129\mecheck\lib\site-packages\django\db\models\query.py", line 1136, in _insert
    return query.get_compiler(using=using).execute_sql(return_id)
  File "C:\Python3129\mecheck\lib\site-packages\django\db\models\sql\compiler.py", line 1289, in execute_sql
    cursor.execute(sql, params)
  File "C:\Python3129\mecheck\lib\site-packages\django\db\backends\utils.py", line 100, in execute
    return super().execute(sql, params)
  File "C:\Python3129\mecheck\lib\site-packages\django\db\backends\utils.py", line 68, in execute
    return self._execute_with_wrappers(sql, params, many=False, executor=self._execute)
  File "C:\Python3129\mecheck\lib\site-packages\django\db\backends\utils.py", line 77, in _execute_with_wrappers
    return executor(sql, params, many, context)
  File "C:\Python3129\mecheck\lib\site-packages\django\db\backends\utils.py", line 85, in _execute
    return self.cursor.execute(sql, params)
  File "C:\Python3129\mecheck\lib\site-packages\django\db\utils.py", line 89, in __exit__
    raise dj_exc_value.with_traceback(traceback) from exc_value
  File "C:\Python3129\mecheck\lib\site-packages\django\db\backends\utils.py", line 85, in _execute
    return self.cursor.execute(sql, params)
  File "C:\Python3129\mecheck\lib\site-packages\django\db\backends\mysql\base.py", line 71, in execute
    return self.cursor.execute(query, args)
  File "C:\Python3129\mecheck\lib\site-packages\pymysql\cursors.py", line 170, in execute
    result = self._query(query)
  File "C:\Python3129\mecheck\lib\site-packages\pymysql\cursors.py", line 328, in _query
    conn.query(q)
  File "C:\Python3129\mecheck\lib\site-packages\pymysql\connections.py", line 517, in query
    self._affected_rows = self._read_query_result(unbuffered=unbuffered)
  File "C:\Python3129\mecheck\lib\site-packages\pymysql\connections.py", line 732, in _read_query_result
    result.read()
  File "C:\Python3129\mecheck\lib\site-packages\pymysql\connections.py", line 1075, in read
    first_packet = self.connection._read_packet()
  File "C:\Python3129\mecheck\lib\site-packages\pymysql\connections.py", line 684, in _read_packet
    packet.check_error()
  File "C:\Python3129\mecheck\lib\site-packages\pymysql\protocol.py", line 220, in check_error
    err.raise_mysql_exception(self._data)
  File "C:\Python3129\mecheck\lib\site-packages\pymysql\err.py", line 109, in raise_mysql_exception
    raise errorclass(errno, errval)
django.db.utils.IntegrityError: (1048, "Column 'Brow_at' cannot be null")
[2025-08-04 14:05:47,735] [UserIP.py:90] [UserIP:process_response] [CRITICAL]- 系统错误Expecting value: line 1 column 1 (char 0)
[2025-08-04 14:05:47,737] [basehttp.py:154] [basehttp:log_message] [ERROR]- "POST /CabinetManage/CabinetManage_edit/ HTTP/1.1" 500 379374
[2025-08-04 14:13:49,081] [log.py:228] [log:log_response] [ERROR]- Internal Server Error: /admin/CabinetManage/cabinet/3/change/
Traceback (most recent call last):
  File "C:\Python3129\mecheck\lib\site-packages\django\contrib\admin\options.py", line 703, in get_form
    return modelform_factory(self.model, **defaults)
  File "C:\Python3129\mecheck\lib\site-packages\django\forms\models.py", line 551, in modelform_factory
    return type(form)(class_name, (form,), form_class_attrs)
  File "C:\Python3129\mecheck\lib\site-packages\django\forms\models.py", line 256, in __new__
    apply_limit_choices_to=False,
  File "C:\Python3129\mecheck\lib\site-packages\django\forms\models.py", line 149, in fields_for_model
    f.name, model.__name__)
django.core.exceptions.FieldError: 'created_at' cannot be specified for Cabinet model form as it is a non-editable field

During handling of the above exception, another exception occurred:

Traceback (most recent call last):
  File "C:\Python3129\mecheck\lib\site-packages\django\core\handlers\exception.py", line 34, in inner
    response = get_response(request)
  File "C:\Python3129\mecheck\lib\site-packages\django\core\handlers\base.py", line 126, in _get_response
    response = self.process_exception_by_middleware(e, request)
  File "C:\Python3129\mecheck\lib\site-packages\django\core\handlers\base.py", line 124, in _get_response
    response = wrapped_callback(request, *callback_args, **callback_kwargs)
  File "C:\Python3129\mecheck\lib\site-packages\django\contrib\admin\options.py", line 604, in wrapper
    return self.admin_site.admin_view(view)(*args, **kwargs)
  File "C:\Python3129\mecheck\lib\site-packages\django\utils\decorators.py", line 142, in _wrapped_view
    response = view_func(request, *args, **kwargs)
  File "C:\Python3129\mecheck\lib\site-packages\django\views\decorators\cache.py", line 44, in _wrapped_view_func
    response = view_func(request, *args, **kwargs)
  File "C:\Python3129\mecheck\lib\site-packages\django\contrib\admin\sites.py", line 223, in inner
    return view(request, *args, **kwargs)
  File "C:\Python3129\mecheck\lib\site-packages\django\contrib\admin\options.py", line 1640, in change_view
    return self.changeform_view(request, object_id, form_url, extra_context)
  File "C:\Python3129\mecheck\lib\site-packages\django\utils\decorators.py", line 45, in _wrapper
    return bound_method(*args, **kwargs)
  File "C:\Python3129\mecheck\lib\site-packages\django\utils\decorators.py", line 142, in _wrapped_view
    response = view_func(request, *args, **kwargs)
  File "C:\Python3129\mecheck\lib\site-packages\django\contrib\admin\options.py", line 1525, in changeform_view
    return self._changeform_view(request, object_id, form_url, extra_context)
  File "C:\Python3129\mecheck\lib\site-packages\django\contrib\admin\options.py", line 1554, in _changeform_view
    ModelForm = self.get_form(request, obj, change=not add)
  File "C:\Python3129\mecheck\lib\site-packages\django\contrib\admin\options.py", line 707, in get_form
    % (e, self.__class__.__name__)
django.core.exceptions.FieldError: 'created_at' cannot be specified for Cabinet model form as it is a non-editable field. Check fields/fieldsets/exclude attributes of class CabinetAdmin.
[2025-08-04 14:13:49,093] [basehttp.py:154] [basehttp:log_message] [ERROR]- "GET /admin/CabinetManage/cabinet/3/change/ HTTP/1.1" 500 151525
[2025-08-04 14:18:09,543] [log.py:228] [log:log_response] [ERROR]- Internal Server Error: /admin/CabinetManage/cabinetgrid/30/change/
Traceback (most recent call last):
  File "C:\Python3129\mecheck\lib\site-packages\django\contrib\admin\options.py", line 703, in get_form
    return modelform_factory(self.model, **defaults)
  File "C:\Python3129\mecheck\lib\site-packages\django\forms\models.py", line 551, in modelform_factory
    return type(form)(class_name, (form,), form_class_attrs)
  File "C:\Python3129\mecheck\lib\site-packages\django\forms\models.py", line 256, in __new__
    apply_limit_choices_to=False,
  File "C:\Python3129\mecheck\lib\site-packages\django\forms\models.py", line 149, in fields_for_model
    f.name, model.__name__)
django.core.exceptions.FieldError: 'created_at' cannot be specified for CabinetGrid model form as it is a non-editable field

During handling of the above exception, another exception occurred:

Traceback (most recent call last):
  File "C:\Python3129\mecheck\lib\site-packages\django\core\handlers\exception.py", line 34, in inner
    response = get_response(request)
  File "C:\Python3129\mecheck\lib\site-packages\django\core\handlers\base.py", line 126, in _get_response
    response = self.process_exception_by_middleware(e, request)
  File "C:\Python3129\mecheck\lib\site-packages\django\core\handlers\base.py", line 124, in _get_response
    response = wrapped_callback(request, *callback_args, **callback_kwargs)
  File "C:\Python3129\mecheck\lib\site-packages\django\contrib\admin\options.py", line 604, in wrapper
    return self.admin_site.admin_view(view)(*args, **kwargs)
  File "C:\Python3129\mecheck\lib\site-packages\django\utils\decorators.py", line 142, in _wrapped_view
    response = view_func(request, *args, **kwargs)
  File "C:\Python3129\mecheck\lib\site-packages\django\views\decorators\cache.py", line 44, in _wrapped_view_func
    response = view_func(request, *args, **kwargs)
  File "C:\Python3129\mecheck\lib\site-packages\django\contrib\admin\sites.py", line 223, in inner
    return view(request, *args, **kwargs)
  File "C:\Python3129\mecheck\lib\site-packages\django\contrib\admin\options.py", line 1640, in change_view
    return self.changeform_view(request, object_id, form_url, extra_context)
  File "C:\Python3129\mecheck\lib\site-packages\django\utils\decorators.py", line 45, in _wrapper
    return bound_method(*args, **kwargs)
  File "C:\Python3129\mecheck\lib\site-packages\django\utils\decorators.py", line 142, in _wrapped_view
    response = view_func(request, *args, **kwargs)
  File "C:\Python3129\mecheck\lib\site-packages\django\contrib\admin\options.py", line 1525, in changeform_view
    return self._changeform_view(request, object_id, form_url, extra_context)
  File "C:\Python3129\mecheck\lib\site-packages\django\contrib\admin\options.py", line 1554, in _changeform_view
    ModelForm = self.get_form(request, obj, change=not add)
  File "C:\Python3129\mecheck\lib\site-packages\django\contrib\admin\options.py", line 707, in get_form
    % (e, self.__class__.__name__)
django.core.exceptions.FieldError: 'created_at' cannot be specified for CabinetGrid model form as it is a non-editable field. Check fields/fieldsets/exclude attributes of class CabinetGridAdmin.
[2025-08-04 14:18:09,545] [basehttp.py:154] [basehttp:log_message] [ERROR]- "GET /admin/CabinetManage/cabinetgrid/30/change/ HTTP/1.1" 500 155059
[2025-08-04 14:18:35,447] [log.py:228] [log:log_response] [ERROR]- Internal Server Error: /admin/CabinetManage/cabinetgrid/30/change/
Traceback (most recent call last):
  File "C:\Python3129\mecheck\lib\site-packages\django\contrib\admin\options.py", line 703, in get_form
    return modelform_factory(self.model, **defaults)
  File "C:\Python3129\mecheck\lib\site-packages\django\forms\models.py", line 551, in modelform_factory
    return type(form)(class_name, (form,), form_class_attrs)
  File "C:\Python3129\mecheck\lib\site-packages\django\forms\models.py", line 256, in __new__
    apply_limit_choices_to=False,
  File "C:\Python3129\mecheck\lib\site-packages\django\forms\models.py", line 149, in fields_for_model
    f.name, model.__name__)
django.core.exceptions.FieldError: 'created_at' cannot be specified for CabinetGrid model form as it is a non-editable field

During handling of the above exception, another exception occurred:

Traceback (most recent call last):
  File "C:\Python3129\mecheck\lib\site-packages\django\core\handlers\exception.py", line 34, in inner
    response = get_response(request)
  File "C:\Python3129\mecheck\lib\site-packages\django\core\handlers\base.py", line 126, in _get_response
    response = self.process_exception_by_middleware(e, request)
  File "C:\Python3129\mecheck\lib\site-packages\django\core\handlers\base.py", line 124, in _get_response
    response = wrapped_callback(request, *callback_args, **callback_kwargs)
  File "C:\Python3129\mecheck\lib\site-packages\django\contrib\admin\options.py", line 604, in wrapper
    return self.admin_site.admin_view(view)(*args, **kwargs)
  File "C:\Python3129\mecheck\lib\site-packages\django\utils\decorators.py", line 142, in _wrapped_view
    response = view_func(request, *args, **kwargs)
  File "C:\Python3129\mecheck\lib\site-packages\django\views\decorators\cache.py", line 44, in _wrapped_view_func
    response = view_func(request, *args, **kwargs)
  File "C:\Python3129\mecheck\lib\site-packages\django\contrib\admin\sites.py", line 223, in inner
    return view(request, *args, **kwargs)
  File "C:\Python3129\mecheck\lib\site-packages\django\contrib\admin\options.py", line 1640, in change_view
    return self.changeform_view(request, object_id, form_url, extra_context)
  File "C:\Python3129\mecheck\lib\site-packages\django\utils\decorators.py", line 45, in _wrapper
    return bound_method(*args, **kwargs)
  File "C:\Python3129\mecheck\lib\site-packages\django\utils\decorators.py", line 142, in _wrapped_view
    response = view_func(request, *args, **kwargs)
  File "C:\Python3129\mecheck\lib\site-packages\django\contrib\admin\options.py", line 1525, in changeform_view
    return self._changeform_view(request, object_id, form_url, extra_context)
  File "C:\Python3129\mecheck\lib\site-packages\django\contrib\admin\options.py", line 1554, in _changeform_view
    ModelForm = self.get_form(request, obj, change=not add)
  File "C:\Python3129\mecheck\lib\site-packages\django\contrib\admin\options.py", line 707, in get_form
    % (e, self.__class__.__name__)
django.core.exceptions.FieldError: 'created_at' cannot be specified for CabinetGrid model form as it is a non-editable field. Check fields/fieldsets/exclude attributes of class CabinetGridAdmin.
[2025-08-04 14:18:35,450] [basehttp.py:154] [basehttp:log_message] [ERROR]- "GET /admin/CabinetManage/cabinetgrid/30/change/ HTTP/1.1" 500 155059
[2025-08-04 14:51:46,463] [log.py:228] [log:log_response] [ERROR]- Internal Server Error: /CabinetManage/CabinetManage_edit/
Traceback (most recent call last):
  File "C:\Python3129\mecheck\lib\site-packages\django\core\handlers\exception.py", line 34, in inner
    response = get_response(request)
  File "C:\Python3129\mecheck\lib\site-packages\django\core\handlers\base.py", line 126, in _get_response
    response = self.process_exception_by_middleware(e, request)
  File "C:\Python3129\mecheck\lib\site-packages\django\core\handlers\base.py", line 124, in _get_response
    response = wrapped_callback(request, *callback_args, **callback_kwargs)
  File "C:\Python3129\mecheck\lib\site-packages\django\views\decorators\csrf.py", line 54, in wrapped_view
    return view_func(*args, **kwargs)
  File "C:\djangoproject\DMS\CabinetManage\views.py", line 242, in CabinetManage_edit
    for j in CabinetGrid.objects.filter(Cabinet=i).values('row'):
  File "C:\Python3129\mecheck\lib\site-packages\django\db\models\manager.py", line 82, in manager_method
    return getattr(self.get_queryset(), name)(*args, **kwargs)
  File "C:\Python3129\mecheck\lib\site-packages\django\db\models\query.py", line 844, in filter
    return self._filter_or_exclude(False, *args, **kwargs)
  File "C:\Python3129\mecheck\lib\site-packages\django\db\models\query.py", line 862, in _filter_or_exclude
    clone.query.add_q(Q(*args, **kwargs))
  File "C:\Python3129\mecheck\lib\site-packages\django\db\models\sql\query.py", line 1263, in add_q
    clause, _ = self._add_q(q_object, self.used_aliases)
  File "C:\Python3129\mecheck\lib\site-packages\django\db\models\sql\query.py", line 1287, in _add_q
    split_subq=split_subq,
  File "C:\Python3129\mecheck\lib\site-packages\django\db\models\sql\query.py", line 1164, in build_filter
    lookups, parts, reffed_expression = self.solve_lookup_type(arg)
  File "C:\Python3129\mecheck\lib\site-packages\django\db\models\sql\query.py", line 1028, in solve_lookup_type
    _, field, _, lookup_parts = self.names_to_path(lookup_splitted, self.get_meta())
  File "C:\Python3129\mecheck\lib\site-packages\django\db\models\sql\query.py", line 1389, in names_to_path
    "Choices are: %s" % (name, ", ".join(available)))
django.core.exceptions.FieldError: Cannot resolve keyword 'Cabinet' into field. Choices are: Back_at, BrowReson, Brow_at, CampalCode, Customer, ProCode, TakeReson, Take_at, cabinet, cabinet_id, col, created_at, creator, id, notes, phone, position, records, row, status, updated_at, user
[2025-08-04 14:51:46,471] [UserIP.py:90] [UserIP:process_response] [CRITICAL]- 系统错误Expecting value: line 1 column 1 (char 0)
[2025-08-04 14:51:46,474] [basehttp.py:154] [basehttp:log_message] [ERROR]- "POST /CabinetManage/CabinetManage_edit/ HTTP/1.1" 500 125558
[2025-08-04 14:52:56,172] [log.py:228] [log:log_response] [ERROR]- Internal Server Error: /CabinetManage/CabinetManage_edit/
Traceback (most recent call last):
  File "C:\Python3129\mecheck\lib\site-packages\django\core\handlers\exception.py", line 34, in inner
    response = get_response(request)
  File "C:\Python3129\mecheck\lib\site-packages\django\core\handlers\base.py", line 126, in _get_response
    response = self.process_exception_by_middleware(e, request)
  File "C:\Python3129\mecheck\lib\site-packages\django\core\handlers\base.py", line 124, in _get_response
    response = wrapped_callback(request, *callback_args, **callback_kwargs)
  File "C:\Python3129\mecheck\lib\site-packages\django\views\decorators\csrf.py", line 54, in wrapped_view
    return view_func(*args, **kwargs)
  File "C:\djangoproject\DMS\CabinetManage\views.py", line 247, in CabinetManage_edit
    'id': celldata.id,
AttributeError: 'QuerySet' object has no attribute 'id'
[2025-08-04 14:52:56,174] [UserIP.py:90] [UserIP:process_response] [CRITICAL]- 系统错误Expecting value: line 1 column 1 (char 0)
[2025-08-04 14:52:56,175] [basehttp.py:154] [basehttp:log_message] [ERROR]- "POST /CabinetManage/CabinetManage_edit/ HTTP/1.1" 500 84428
[2025-08-04 14:53:48,149] [log.py:228] [log:log_response] [ERROR]- Internal Server Error: /CabinetManage/CabinetManage_edit/
Traceback (most recent call last):
  File "C:\Python3129\mecheck\lib\site-packages\django\core\handlers\exception.py", line 34, in inner
    response = get_response(request)
  File "C:\Python3129\mecheck\lib\site-packages\django\core\handlers\base.py", line 126, in _get_response
    response = self.process_exception_by_middleware(e, request)
  File "C:\Python3129\mecheck\lib\site-packages\django\core\handlers\base.py", line 124, in _get_response
    response = wrapped_callback(request, *callback_args, **callback_kwargs)
  File "C:\Python3129\mecheck\lib\site-packages\django\views\decorators\csrf.py", line 54, in wrapped_view
    return view_func(*args, **kwargs)
  File "C:\djangoproject\DMS\CabinetManage\views.py", line 245, in CabinetManage_edit
    celldata = CabinetGrid.objects.filter(cabinet=i, row=j['row'], col=k['col']).fir
AttributeError: 'QuerySet' object has no attribute 'fir'
[2025-08-04 14:53:48,151] [UserIP.py:90] [UserIP:process_response] [CRITICAL]- 系统错误Expecting value: line 1 column 1 (char 0)
[2025-08-04 14:53:48,152] [basehttp.py:154] [basehttp:log_message] [ERROR]- "POST /CabinetManage/CabinetManage_edit/ HTTP/1.1" 500 84180
[2025-08-04 15:05:36,143] [log.py:228] [log:log_response] [ERROR]- Internal Server Error: /CabinetManage/CabinetManage_edit/
Traceback (most recent call last):
  File "C:\Python3129\mecheck\lib\site-packages\django\core\handlers\exception.py", line 34, in inner
    response = get_response(request)
  File "C:\Python3129\mecheck\lib\site-packages\django\core\handlers\base.py", line 126, in _get_response
    response = self.process_exception_by_middleware(e, request)
  File "C:\Python3129\mecheck\lib\site-packages\django\core\handlers\base.py", line 124, in _get_response
    response = wrapped_callback(request, *callback_args, **callback_kwargs)
  File "C:\Python3129\mecheck\lib\site-packages\django\views\decorators\csrf.py", line 54, in wrapped_view
    return view_func(*args, **kwargs)
  File "C:\djangoproject\DMS\CabinetManage\views.py", line 243, in CabinetManage_edit
    print(i['row'])
TypeError: 'Cabinet' object is not subscriptable
[2025-08-04 15:05:36,145] [UserIP.py:90] [UserIP:process_response] [CRITICAL]- 系统错误Expecting value: line 1 column 1 (char 0)
[2025-08-04 15:05:36,145] [basehttp.py:154] [basehttp:log_message] [ERROR]- "POST /CabinetManage/CabinetManage_edit/ HTTP/1.1" 500 83555
[2025-08-04 15:18:14,298] [UserIP.py:90] [UserIP:process_response] [CRITICAL]- 系统错误Expecting value: line 1 column 1 (char 0)
[2025-08-04 15:18:16,196] [UserIP.py:90] [UserIP:process_response] [CRITICAL]- 系统错误Expecting value: line 1 column 1 (char 0)
[2025-08-04 15:18:20,744] [UserIP.py:90] [UserIP:process_response] [CRITICAL]- 系统错误Expecting value: line 1 column 1 (char 0)
[2025-08-04 15:18:26,814] [UserIP.py:90] [UserIP:process_response] [CRITICAL]- 系统错误Expecting value: line 1 column 1 (char 0)
[2025-08-04 17:01:51,073] [log.py:228] [log:log_response] [ERROR]- Internal Server Error: /CabinetManage/CabinetManage_edit/
Traceback (most recent call last):
  File "C:\Python3129\mecheck\lib\site-packages\django\core\handlers\exception.py", line 34, in inner
    response = get_response(request)
  File "C:\Python3129\mecheck\lib\site-packages\django\core\handlers\base.py", line 126, in _get_response
    response = self.process_exception_by_middleware(e, request)
  File "C:\Python3129\mecheck\lib\site-packages\django\core\handlers\base.py", line 124, in _get_response
    response = wrapped_callback(request, *callback_args, **callback_kwargs)
  File "C:\Python3129\mecheck\lib\site-packages\django\views\decorators\csrf.py", line 54, in wrapped_view
    return view_func(*args, **kwargs)
  File "C:\djangoproject\DMS\CabinetManage\views.py", line 245, in CabinetManage_edit
    "Customer": responseData['Customer'],
KeyError: 'Customer'
[2025-08-04 17:01:51,081] [UserIP.py:90] [UserIP:process_response] [CRITICAL]- 系统错误Expecting value: line 1 column 1 (char 0)
[2025-08-04 17:01:51,084] [basehttp.py:154] [basehttp:log_message] [ERROR]- "POST /CabinetManage/CabinetManage_edit/ HTTP/1.1" 500 83826
[2025-08-05 07:53:53,653] [UserIP.py:90] [UserIP:process_response] [CRITICAL]- 系统错误Expecting value: line 1 column 1 (char 0)
