[2025-08-01 12:09:38,923] [UserIP.py:90] [UserIP:process_response] [CRITICAL]- 系统错误Expecting value: line 1 column 1 (char 0)
[2025-08-01 12:09:56,887] [log.py:228] [log:log_response] [ERROR]- Internal Server Error: /admin/CabinetManage/devicea39/
Traceback (most recent call last):
  File "C:\Python3129\mecheck\lib\site-packages\django\db\backends\utils.py", line 85, in _execute
    return self.cursor.execute(sql, params)
  File "C:\Python3129\mecheck\lib\site-packages\django\db\backends\mysql\base.py", line 71, in execute
    return self.cursor.execute(query, args)
  File "C:\Python3129\mecheck\lib\site-packages\pymysql\cursors.py", line 170, in execute
    result = self._query(query)
  File "C:\Python3129\mecheck\lib\site-packages\pymysql\cursors.py", line 328, in _query
    conn.query(q)
  File "C:\Python3129\mecheck\lib\site-packages\pymysql\connections.py", line 517, in query
    self._affected_rows = self._read_query_result(unbuffered=unbuffered)
  File "C:\Python3129\mecheck\lib\site-packages\pymysql\connections.py", line 732, in _read_query_result
    result.read()
  File "C:\Python3129\mecheck\lib\site-packages\pymysql\connections.py", line 1075, in read
    first_packet = self.connection._read_packet()
  File "C:\Python3129\mecheck\lib\site-packages\pymysql\connections.py", line 684, in _read_packet
    packet.check_error()
  File "C:\Python3129\mecheck\lib\site-packages\pymysql\protocol.py", line 220, in check_error
    err.raise_mysql_exception(self._data)
  File "C:\Python3129\mecheck\lib\site-packages\pymysql\err.py", line 109, in raise_mysql_exception
    raise errorclass(errno, errval)
pymysql.err.ProgrammingError: (1146, "Table 'dms.cabinetmanage_devicea39' doesn't exist")

The above exception was the direct cause of the following exception:

Traceback (most recent call last):
  File "C:\Python3129\mecheck\lib\site-packages\django\core\handlers\exception.py", line 34, in inner
    response = get_response(request)
  File "C:\Python3129\mecheck\lib\site-packages\django\core\handlers\base.py", line 126, in _get_response
    response = self.process_exception_by_middleware(e, request)
  File "C:\Python3129\mecheck\lib\site-packages\django\core\handlers\base.py", line 124, in _get_response
    response = wrapped_callback(request, *callback_args, **callback_kwargs)
  File "C:\Python3129\mecheck\lib\site-packages\django\contrib\admin\options.py", line 604, in wrapper
    return self.admin_site.admin_view(view)(*args, **kwargs)
  File "C:\Python3129\mecheck\lib\site-packages\django\utils\decorators.py", line 142, in _wrapped_view
    response = view_func(request, *args, **kwargs)
  File "C:\Python3129\mecheck\lib\site-packages\django\views\decorators\cache.py", line 44, in _wrapped_view_func
    response = view_func(request, *args, **kwargs)
  File "C:\Python3129\mecheck\lib\site-packages\django\contrib\admin\sites.py", line 223, in inner
    return view(request, *args, **kwargs)
  File "C:\Python3129\mecheck\lib\site-packages\django\utils\decorators.py", line 45, in _wrapper
    return bound_method(*args, **kwargs)
  File "C:\Python3129\mecheck\lib\site-packages\django\utils\decorators.py", line 142, in _wrapped_view
    response = view_func(request, *args, **kwargs)
  File "C:\Python3129\mecheck\lib\site-packages\django\contrib\admin\options.py", line 1675, in changelist_view
    cl = self.get_changelist_instance(request)
  File "C:\Python3129\mecheck\lib\site-packages\django\contrib\admin\options.py", line 742, in get_changelist_instance
    sortable_by,
  File "C:\Python3129\mecheck\lib\site-packages\django\contrib\admin\views\main.py", line 81, in __init__
    self.get_results(request)
  File "C:\Python3129\mecheck\lib\site-packages\django\contrib\admin\views\main.py", line 209, in get_results
    result_count = paginator.count
  File "C:\Python3129\mecheck\lib\site-packages\django\utils\functional.py", line 37, in __get__
    res = instance.__dict__[self.name] = self.func(instance)
  File "C:\Python3129\mecheck\lib\site-packages\django\core\paginator.py", line 87, in count
    return self.object_list.count()
  File "C:\Python3129\mecheck\lib\site-packages\django\db\models\query.py", line 383, in count
    return self.query.get_count(using=self.db)
  File "C:\Python3129\mecheck\lib\site-packages\django\db\models\sql\query.py", line 498, in get_count
    number = obj.get_aggregation(using, ['__count'])['__count']
  File "C:\Python3129\mecheck\lib\site-packages\django\db\models\sql\query.py", line 483, in get_aggregation
    result = compiler.execute_sql(SINGLE)
  File "C:\Python3129\mecheck\lib\site-packages\django\db\models\sql\compiler.py", line 1065, in execute_sql
    cursor.execute(sql, params)
  File "C:\Python3129\mecheck\lib\site-packages\django\db\backends\utils.py", line 100, in execute
    return super().execute(sql, params)
  File "C:\Python3129\mecheck\lib\site-packages\django\db\backends\utils.py", line 68, in execute
    return self._execute_with_wrappers(sql, params, many=False, executor=self._execute)
  File "C:\Python3129\mecheck\lib\site-packages\django\db\backends\utils.py", line 77, in _execute_with_wrappers
    return executor(sql, params, many, context)
  File "C:\Python3129\mecheck\lib\site-packages\django\db\backends\utils.py", line 85, in _execute
    return self.cursor.execute(sql, params)
  File "C:\Python3129\mecheck\lib\site-packages\django\db\utils.py", line 89, in __exit__
    raise dj_exc_value.with_traceback(traceback) from exc_value
  File "C:\Python3129\mecheck\lib\site-packages\django\db\backends\utils.py", line 85, in _execute
    return self.cursor.execute(sql, params)
  File "C:\Python3129\mecheck\lib\site-packages\django\db\backends\mysql\base.py", line 71, in execute
    return self.cursor.execute(query, args)
  File "C:\Python3129\mecheck\lib\site-packages\pymysql\cursors.py", line 170, in execute
    result = self._query(query)
  File "C:\Python3129\mecheck\lib\site-packages\pymysql\cursors.py", line 328, in _query
    conn.query(q)
  File "C:\Python3129\mecheck\lib\site-packages\pymysql\connections.py", line 517, in query
    self._affected_rows = self._read_query_result(unbuffered=unbuffered)
  File "C:\Python3129\mecheck\lib\site-packages\pymysql\connections.py", line 732, in _read_query_result
    result.read()
  File "C:\Python3129\mecheck\lib\site-packages\pymysql\connections.py", line 1075, in read
    first_packet = self.connection._read_packet()
  File "C:\Python3129\mecheck\lib\site-packages\pymysql\connections.py", line 684, in _read_packet
    packet.check_error()
  File "C:\Python3129\mecheck\lib\site-packages\pymysql\protocol.py", line 220, in check_error
    err.raise_mysql_exception(self._data)
  File "C:\Python3129\mecheck\lib\site-packages\pymysql\err.py", line 109, in raise_mysql_exception
    raise errorclass(errno, errval)
django.db.utils.ProgrammingError: (1146, "Table 'dms.cabinetmanage_devicea39' doesn't exist")
[2025-08-01 12:09:56,926] [basehttp.py:154] [basehttp:log_message] [ERROR]- "GET /admin/CabinetManage/devicea39/ HTTP/1.1" 500 256249
[2025-08-01 12:12:07,356] [UserIP.py:90] [UserIP:process_response] [CRITICAL]- 系统错误Expecting value: line 1 column 1 (char 0)
[2025-08-01 12:14:16,979] [UserIP.py:90] [UserIP:process_response] [CRITICAL]- 系统错误Expecting value: line 1 column 1 (char 0)
[2025-08-01 12:32:12,968] [UserIP.py:90] [UserIP:process_response] [CRITICAL]- 系统错误Expecting value: line 1 column 1 (char 0)
[2025-08-01 12:32:31,078] [UserIP.py:90] [UserIP:process_response] [CRITICAL]- 系统错误Expecting value: line 1 column 1 (char 0)
[2025-08-01 12:37:45,094] [UserIP.py:90] [UserIP:process_response] [CRITICAL]- 系统错误Expecting value: line 1 column 1 (char 0)
[2025-08-01 12:37:54,418] [log.py:228] [log:log_response] [ERROR]- Internal Server Error: /CabinetManage/CabinetManage_edit/
Traceback (most recent call last):
  File "C:\Python3129\mecheck\lib\site-packages\django\db\backends\utils.py", line 85, in _execute
    return self.cursor.execute(sql, params)
  File "C:\Python3129\mecheck\lib\site-packages\django\db\backends\mysql\base.py", line 71, in execute
    return self.cursor.execute(query, args)
  File "C:\Python3129\mecheck\lib\site-packages\pymysql\cursors.py", line 170, in execute
    result = self._query(query)
  File "C:\Python3129\mecheck\lib\site-packages\pymysql\cursors.py", line 328, in _query
    conn.query(q)
  File "C:\Python3129\mecheck\lib\site-packages\pymysql\connections.py", line 517, in query
    self._affected_rows = self._read_query_result(unbuffered=unbuffered)
  File "C:\Python3129\mecheck\lib\site-packages\pymysql\connections.py", line 732, in _read_query_result
    result.read()
  File "C:\Python3129\mecheck\lib\site-packages\pymysql\connections.py", line 1075, in read
    first_packet = self.connection._read_packet()
  File "C:\Python3129\mecheck\lib\site-packages\pymysql\connections.py", line 684, in _read_packet
    packet.check_error()
  File "C:\Python3129\mecheck\lib\site-packages\pymysql\protocol.py", line 220, in check_error
    err.raise_mysql_exception(self._data)
  File "C:\Python3129\mecheck\lib\site-packages\pymysql\err.py", line 109, in raise_mysql_exception
    raise errorclass(errno, errval)
pymysql.err.ProgrammingError: (1146, "Table 'dms.cabinetmanage_deviceintfctgrylist' doesn't exist")

The above exception was the direct cause of the following exception:

Traceback (most recent call last):
  File "C:\Python3129\mecheck\lib\site-packages\django\core\handlers\exception.py", line 34, in inner
    response = get_response(request)
  File "C:\Python3129\mecheck\lib\site-packages\django\core\handlers\base.py", line 126, in _get_response
    response = self.process_exception_by_middleware(e, request)
  File "C:\Python3129\mecheck\lib\site-packages\django\core\handlers\base.py", line 124, in _get_response
    response = wrapped_callback(request, *callback_args, **callback_kwargs)
  File "C:\Python3129\mecheck\lib\site-packages\django\views\decorators\csrf.py", line 54, in wrapped_view
    return view_func(*args, **kwargs)
  File "C:\djangoproject\DMS\CabinetManage\views.py", line 96, in CabinetManage_edit
    if DeviceIntfCtgryList.objects.all():
  File "C:\Python3129\mecheck\lib\site-packages\django\db\models\query.py", line 272, in __bool__
    self._fetch_all()
  File "C:\Python3129\mecheck\lib\site-packages\django\db\models\query.py", line 1186, in _fetch_all
    self._result_cache = list(self._iterable_class(self))
  File "C:\Python3129\mecheck\lib\site-packages\django\db\models\query.py", line 54, in __iter__
    results = compiler.execute_sql(chunked_fetch=self.chunked_fetch, chunk_size=self.chunk_size)
  File "C:\Python3129\mecheck\lib\site-packages\django\db\models\sql\compiler.py", line 1065, in execute_sql
    cursor.execute(sql, params)
  File "C:\Python3129\mecheck\lib\site-packages\django\db\backends\utils.py", line 100, in execute
    return super().execute(sql, params)
  File "C:\Python3129\mecheck\lib\site-packages\django\db\backends\utils.py", line 68, in execute
    return self._execute_with_wrappers(sql, params, many=False, executor=self._execute)
  File "C:\Python3129\mecheck\lib\site-packages\django\db\backends\utils.py", line 77, in _execute_with_wrappers
    return executor(sql, params, many, context)
  File "C:\Python3129\mecheck\lib\site-packages\django\db\backends\utils.py", line 85, in _execute
    return self.cursor.execute(sql, params)
  File "C:\Python3129\mecheck\lib\site-packages\django\db\utils.py", line 89, in __exit__
    raise dj_exc_value.with_traceback(traceback) from exc_value
  File "C:\Python3129\mecheck\lib\site-packages\django\db\backends\utils.py", line 85, in _execute
    return self.cursor.execute(sql, params)
  File "C:\Python3129\mecheck\lib\site-packages\django\db\backends\mysql\base.py", line 71, in execute
    return self.cursor.execute(query, args)
  File "C:\Python3129\mecheck\lib\site-packages\pymysql\cursors.py", line 170, in execute
    result = self._query(query)
  File "C:\Python3129\mecheck\lib\site-packages\pymysql\cursors.py", line 328, in _query
    conn.query(q)
  File "C:\Python3129\mecheck\lib\site-packages\pymysql\connections.py", line 517, in query
    self._affected_rows = self._read_query_result(unbuffered=unbuffered)
  File "C:\Python3129\mecheck\lib\site-packages\pymysql\connections.py", line 732, in _read_query_result
    result.read()
  File "C:\Python3129\mecheck\lib\site-packages\pymysql\connections.py", line 1075, in read
    first_packet = self.connection._read_packet()
  File "C:\Python3129\mecheck\lib\site-packages\pymysql\connections.py", line 684, in _read_packet
    packet.check_error()
  File "C:\Python3129\mecheck\lib\site-packages\pymysql\protocol.py", line 220, in check_error
    err.raise_mysql_exception(self._data)
  File "C:\Python3129\mecheck\lib\site-packages\pymysql\err.py", line 109, in raise_mysql_exception
    raise errorclass(errno, errval)
django.db.utils.ProgrammingError: (1146, "Table 'dms.cabinetmanage_deviceintfctgrylist' doesn't exist")
[2025-08-01 12:37:54,433] [basehttp.py:154] [basehttp:log_message] [ERROR]- "GET /CabinetManage/CabinetManage_edit/ HTTP/1.1" 500 205991
[2025-08-01 12:41:01,971] [UserIP.py:90] [UserIP:process_response] [CRITICAL]- 系统错误Expecting value: line 1 column 1 (char 0)
[2025-08-01 12:41:25,640] [UserIP.py:90] [UserIP:process_response] [CRITICAL]- 系统错误Expecting value: line 1 column 1 (char 0)
[2025-08-01 12:41:36,154] [UserIP.py:90] [UserIP:process_response] [CRITICAL]- 系统错误Expecting value: line 1 column 1 (char 0)
[2025-08-01 12:41:43,215] [UserIP.py:90] [UserIP:process_response] [CRITICAL]- 系统错误Expecting value: line 1 column 1 (char 0)
[2025-08-01 13:55:37,864] [UserIP.py:90] [UserIP:process_response] [CRITICAL]- 系统错误Expecting value: line 1 column 1 (char 0)
